[2023-06-08 10:32:20,825] {taskinstance.py:896} INFO - Dependencies all met for <TaskInstance: 1_init_once_seed_data.load_seed_data_once 2023-06-08T10:32:20.233639+00:00 [queued]>
[2023-06-08 10:32:20,845] {taskinstance.py:896} INFO - Dependencies all met for <TaskInstance: 1_init_once_seed_data.load_seed_data_once 2023-06-08T10:32:20.233639+00:00 [queued]>
[2023-06-08 10:32:20,846] {taskinstance.py:1087} INFO - 
--------------------------------------------------------------------------------
[2023-06-08 10:32:20,847] {taskinstance.py:1088} INFO - Starting attempt 1 of 1
[2023-06-08 10:32:20,848] {taskinstance.py:1089} INFO - 
--------------------------------------------------------------------------------
[2023-06-08 10:32:20,858] {taskinstance.py:1107} INFO - Executing <Task(BashOperator): load_seed_data_once> on 2023-06-08T10:32:20.233639+00:00
[2023-06-08 10:32:20,867] {standard_task_runner.py:76} INFO - Running: ['***', 'tasks', 'run', '1_init_once_seed_data', 'load_seed_data_once', '2023-06-08T10:32:20.233639+00:00', '--job-id', '26', '--pool', 'default_pool', '--raw', '--subdir', 'DAGS_FOLDER/init.py', '--cfg-path', '/tmp/tmp5ojh8swz', '--error-file', '/tmp/tmp5ga1rink']
[2023-06-08 10:32:20,862] {standard_task_runner.py:52} INFO - Started process 377 to run task
[2023-06-08 10:32:20,869] {standard_task_runner.py:77} INFO - Job 26: Subtask load_seed_data_once
[2023-06-08 10:32:20,919] {logging_mixin.py:104} INFO - Running <TaskInstance: 1_init_once_seed_data.load_seed_data_once 2023-06-08T10:32:20.233639+00:00 [running]> on host 1e9c7bef4812
[2023-06-08 10:32:20,982] {taskinstance.py:1302} INFO - Exporting the following env vars:
AIRFLOW_CTX_DAG_OWNER=***
AIRFLOW_CTX_DAG_ID=1_init_once_seed_data
AIRFLOW_CTX_TASK_ID=load_seed_data_once
AIRFLOW_CTX_EXECUTION_DATE=2023-06-08T10:32:20.233639+00:00
AIRFLOW_CTX_DAG_RUN_ID=manual__2023-06-08T10:32:20.233639+00:00
[2023-06-08 10:32:20,984] {subprocess.py:52} INFO - Tmp dir root location: 
 /tmp
[2023-06-08 10:32:20,985] {subprocess.py:63} INFO - Running command: ['bash', '-c', 'cd /dbt && dbt seed --profiles-dir .']
[2023-06-08 10:32:20,995] {subprocess.py:74} INFO - Output:
[2023-06-08 10:32:22,888] {subprocess.py:78} INFO - Running with dbt=0.19.0
[2023-06-08 10:32:22,907] {subprocess.py:78} INFO - Encountered an error while reading the project:
[2023-06-08 10:32:22,908] {subprocess.py:78} INFO -   ERROR: Runtime Error
[2023-06-08 10:32:22,909] {subprocess.py:78} INFO -   Could not find profile named 'Airflow_DBT_Snowflake'
[2023-06-08 10:32:22,916] {subprocess.py:78} INFO - Encountered an error:
[2023-06-08 10:32:22,917] {subprocess.py:78} INFO - Runtime Error
[2023-06-08 10:32:22,917] {subprocess.py:78} INFO -   Could not run dbt
[2023-06-08 10:32:23,072] {subprocess.py:82} INFO - Command exited with return code 2
[2023-06-08 10:32:23,084] {taskinstance.py:1501} ERROR - Task failed with exception
Traceback (most recent call last):
  File "/home/airflow/.local/lib/python3.6/site-packages/airflow/models/taskinstance.py", line 1157, in _run_raw_task
    self._prepare_and_execute_task_with_callbacks(context, task)
  File "/home/airflow/.local/lib/python3.6/site-packages/airflow/models/taskinstance.py", line 1331, in _prepare_and_execute_task_with_callbacks
    result = self._execute_task(context, task_copy)
  File "/home/airflow/.local/lib/python3.6/site-packages/airflow/models/taskinstance.py", line 1361, in _execute_task
    result = task_copy.execute(context=context)
  File "/home/airflow/.local/lib/python3.6/site-packages/airflow/operators/bash.py", line 176, in execute
    raise AirflowException('Bash command failed. The command returned a non-zero exit code.')
airflow.exceptions.AirflowException: Bash command failed. The command returned a non-zero exit code.
[2023-06-08 10:32:23,087] {taskinstance.py:1551} INFO - Marking task as FAILED. dag_id=1_init_once_seed_data, task_id=load_seed_data_once, execution_date=20230608T103220, start_date=20230608T103220, end_date=20230608T103223
[2023-06-08 10:32:23,133] {local_task_job.py:149} INFO - Task exited with return code 1
