[2023-06-09 09:01:51,113] {taskinstance.py:896} INFO - Dependencies all met for <TaskInstance: 1_init_once_seed_data.load_seed_data_once 2023-06-09T09:01:49.396059+00:00 [queued]>
[2023-06-09 09:01:51,127] {taskinstance.py:896} INFO - Dependencies all met for <TaskInstance: 1_init_once_seed_data.load_seed_data_once 2023-06-09T09:01:49.396059+00:00 [queued]>
[2023-06-09 09:01:51,128] {taskinstance.py:1087} INFO - 
--------------------------------------------------------------------------------
[2023-06-09 09:01:51,129] {taskinstance.py:1088} INFO - Starting attempt 1 of 1
[2023-06-09 09:01:51,129] {taskinstance.py:1089} INFO - 
--------------------------------------------------------------------------------
[2023-06-09 09:01:51,139] {taskinstance.py:1107} INFO - Executing <Task(BashOperator): load_seed_data_once> on 2023-06-09T09:01:49.396059+00:00
[2023-06-09 09:01:51,147] {standard_task_runner.py:76} INFO - Running: ['***', 'tasks', 'run', '1_init_once_seed_data', 'load_seed_data_once', '2023-06-09T09:01:49.396059+00:00', '--job-id', '33', '--pool', 'default_pool', '--raw', '--subdir', 'DAGS_FOLDER/init.py', '--cfg-path', '/tmp/tmpqr7spew9', '--error-file', '/tmp/tmp1p3d4el5']
[2023-06-09 09:01:51,143] {standard_task_runner.py:52} INFO - Started process 128 to run task
[2023-06-09 09:01:51,148] {standard_task_runner.py:77} INFO - Job 33: Subtask load_seed_data_once
[2023-06-09 09:01:51,189] {logging_mixin.py:104} INFO - Running <TaskInstance: 1_init_once_seed_data.load_seed_data_once 2023-06-09T09:01:49.396059+00:00 [running]> on host 96743bcaa63a
[2023-06-09 09:01:51,233] {taskinstance.py:1302} INFO - Exporting the following env vars:
AIRFLOW_CTX_DAG_OWNER=***
AIRFLOW_CTX_DAG_ID=1_init_once_seed_data
AIRFLOW_CTX_TASK_ID=load_seed_data_once
AIRFLOW_CTX_EXECUTION_DATE=2023-06-09T09:01:49.396059+00:00
AIRFLOW_CTX_DAG_RUN_ID=manual__2023-06-09T09:01:49.396059+00:00
[2023-06-09 09:01:51,235] {subprocess.py:52} INFO - Tmp dir root location: 
 /tmp
[2023-06-09 09:01:51,236] {subprocess.py:63} INFO - Running command: ['bash', '-c', 'cd /dbt && dbt seed --profiles-dir .']
[2023-06-09 09:01:51,243] {subprocess.py:74} INFO - Output:
[2023-06-09 09:01:52,834] {subprocess.py:78} INFO - Running with dbt=0.19.0
[2023-06-09 09:01:52,853] {subprocess.py:78} INFO - Encountered an error while reading the project:
[2023-06-09 09:01:52,854] {subprocess.py:78} INFO -   ERROR: Runtime Error
[2023-06-09 09:01:52,855] {subprocess.py:78} INFO -   Could not find profile named 'Airflow_DBT_Snowflake'
[2023-06-09 09:01:52,861] {subprocess.py:78} INFO - Encountered an error:
[2023-06-09 09:01:52,862] {subprocess.py:78} INFO - Runtime Error
[2023-06-09 09:01:52,862] {subprocess.py:78} INFO -   Could not run dbt
[2023-06-09 09:01:52,990] {subprocess.py:82} INFO - Command exited with return code 2
[2023-06-09 09:01:53,002] {taskinstance.py:1501} ERROR - Task failed with exception
Traceback (most recent call last):
  File "/home/airflow/.local/lib/python3.6/site-packages/airflow/models/taskinstance.py", line 1157, in _run_raw_task
    self._prepare_and_execute_task_with_callbacks(context, task)
  File "/home/airflow/.local/lib/python3.6/site-packages/airflow/models/taskinstance.py", line 1331, in _prepare_and_execute_task_with_callbacks
    result = self._execute_task(context, task_copy)
  File "/home/airflow/.local/lib/python3.6/site-packages/airflow/models/taskinstance.py", line 1361, in _execute_task
    result = task_copy.execute(context=context)
  File "/home/airflow/.local/lib/python3.6/site-packages/airflow/operators/bash.py", line 176, in execute
    raise AirflowException('Bash command failed. The command returned a non-zero exit code.')
airflow.exceptions.AirflowException: Bash command failed. The command returned a non-zero exit code.
[2023-06-09 09:01:53,004] {taskinstance.py:1551} INFO - Marking task as FAILED. dag_id=1_init_once_seed_data, task_id=load_seed_data_once, execution_date=20230609T090149, start_date=20230609T090151, end_date=20230609T090153
[2023-06-09 09:01:53,049] {local_task_job.py:149} INFO - Task exited with return code 1
