[2023-06-08 08:53:59,209] {taskinstance.py:896} INFO - Dependencies all met for <TaskInstance: 1_init_once_seed_data.load_seed_data_once 2023-06-08T08:53:57.713014+00:00 [queued]>
[2023-06-08 08:53:59,220] {taskinstance.py:896} INFO - Dependencies all met for <TaskInstance: 1_init_once_seed_data.load_seed_data_once 2023-06-08T08:53:57.713014+00:00 [queued]>
[2023-06-08 08:53:59,221] {taskinstance.py:1087} INFO - 
--------------------------------------------------------------------------------
[2023-06-08 08:53:59,222] {taskinstance.py:1088} INFO - Starting attempt 1 of 1
[2023-06-08 08:53:59,223] {taskinstance.py:1089} INFO - 
--------------------------------------------------------------------------------
[2023-06-08 08:53:59,237] {taskinstance.py:1107} INFO - Executing <Task(BashOperator): load_seed_data_once> on 2023-06-08T08:53:57.713014+00:00
[2023-06-08 08:53:59,242] {standard_task_runner.py:52} INFO - Started process 1294 to run task
[2023-06-08 08:53:59,247] {standard_task_runner.py:76} INFO - Running: ['***', 'tasks', 'run', '1_init_once_seed_data', 'load_seed_data_once', '2023-06-08T08:53:57.713014+00:00', '--job-id', '8', '--pool', 'default_pool', '--raw', '--subdir', 'DAGS_FOLDER/init.py', '--cfg-path', '/tmp/tmpd5b3ceb6', '--error-file', '/tmp/tmplaidbqxc']
[2023-06-08 08:53:59,248] {standard_task_runner.py:77} INFO - Job 8: Subtask load_seed_data_once
[2023-06-08 08:53:59,294] {logging_mixin.py:104} INFO - Running <TaskInstance: 1_init_once_seed_data.load_seed_data_once 2023-06-08T08:53:57.713014+00:00 [running]> on host 1e9c7bef4812
[2023-06-08 08:53:59,349] {taskinstance.py:1302} INFO - Exporting the following env vars:
AIRFLOW_CTX_DAG_OWNER=***
AIRFLOW_CTX_DAG_ID=1_init_once_seed_data
AIRFLOW_CTX_TASK_ID=load_seed_data_once
AIRFLOW_CTX_EXECUTION_DATE=2023-06-08T08:53:57.713014+00:00
AIRFLOW_CTX_DAG_RUN_ID=manual__2023-06-08T08:53:57.713014+00:00
[2023-06-08 08:53:59,351] {subprocess.py:52} INFO - Tmp dir root location: 
 /tmp
[2023-06-08 08:53:59,352] {subprocess.py:63} INFO - Running command: ['bash', '-c', 'cd /dbt && dbt seed --profiles-dir .']
[2023-06-08 08:53:59,362] {subprocess.py:74} INFO - Output:
[2023-06-08 08:54:01,080] {subprocess.py:78} INFO - Running with dbt=0.19.0
[2023-06-08 08:54:01,100] {subprocess.py:78} INFO - Encountered an error while reading the project:
[2023-06-08 08:54:01,101] {subprocess.py:78} INFO -   ERROR: Runtime Error
[2023-06-08 08:54:01,102] {subprocess.py:78} INFO -   Could not find profile named 'Airflow_DBT_Snowflake'
[2023-06-08 08:54:01,110] {subprocess.py:78} INFO - Encountered an error:
[2023-06-08 08:54:01,111] {subprocess.py:78} INFO - Runtime Error
[2023-06-08 08:54:01,111] {subprocess.py:78} INFO -   Could not run dbt
[2023-06-08 08:54:01,253] {subprocess.py:82} INFO - Command exited with return code 2
[2023-06-08 08:54:01,319] {taskinstance.py:1501} ERROR - Task failed with exception
Traceback (most recent call last):
  File "/home/airflow/.local/lib/python3.6/site-packages/airflow/models/taskinstance.py", line 1157, in _run_raw_task
    self._prepare_and_execute_task_with_callbacks(context, task)
  File "/home/airflow/.local/lib/python3.6/site-packages/airflow/models/taskinstance.py", line 1331, in _prepare_and_execute_task_with_callbacks
    result = self._execute_task(context, task_copy)
  File "/home/airflow/.local/lib/python3.6/site-packages/airflow/models/taskinstance.py", line 1361, in _execute_task
    result = task_copy.execute(context=context)
  File "/home/airflow/.local/lib/python3.6/site-packages/airflow/operators/bash.py", line 176, in execute
    raise AirflowException('Bash command failed. The command returned a non-zero exit code.')
airflow.exceptions.AirflowException: Bash command failed. The command returned a non-zero exit code.
[2023-06-08 08:54:01,323] {taskinstance.py:1551} INFO - Marking task as FAILED. dag_id=1_init_once_seed_data, task_id=load_seed_data_once, execution_date=20230608T085357, start_date=20230608T085359, end_date=20230608T085401
[2023-06-08 08:54:01,372] {local_task_job.py:149} INFO - Task exited with return code 1
